Checking for script in /app/prestart.sh
There is no script /app/prestart.sh
{"loglevel": "info", "workers": 3, "bind": "0.0.0.0:80", "graceful_timeout": 120, "timeout": 120, "keepalive": 5, "errorlog": "-", "accesslog": "-", "workers_per_core": 1.0, "use_max_workers": null, "host": "0.0.0.0", "port": "80"}
[2025-02-05 17:40:59 +0000] [1] [INFO] Starting gunicorn 23.0.0
[2025-02-05 17:40:59 +0000] [1] [INFO] Listening at: http://0.0.0.0:80 (1)
[2025-02-05 17:40:59 +0000] [1] [INFO] Using worker: uvicorn.workers.UvicornWorker
[2025-02-05 17:40:59 +0000] [7] [INFO] Booting worker with pid: 7
[2025-02-05 17:40:59 +0000] [7] [ERROR] Exception in worker process
Traceback (most recent call last):
  File "/usr/local/lib/python3.9/site-packages/gunicorn/arbiter.py", line 608, in spawn_worker
    worker.init_process()
  File "/usr/local/lib/python3.9/site-packages/uvicorn/workers.py", line 75, in init_process
    super().init_process()
  File "/usr/local/lib/python3.9/site-packages/gunicorn/workers/base.py", line 135, in init_process
    self.load_wsgi()
  File "/usr/local/lib/python3.9/site-packages/gunicorn/workers/base.py", line 147, in load_wsgi
    self.wsgi = self.app.wsgi()
  File "/usr/local/lib/python3.9/site-packages/gunicorn/app/base.py", line 66, in wsgi
    self.callable = self.load()
  File "/usr/local/lib/python3.9/site-packages/gunicorn/app/wsgiapp.py", line 57, in load
    return self.load_wsgiapp()
  File "/usr/local/lib/python3.9/site-packages/gunicorn/app/wsgiapp.py", line 47, in load_wsgiapp
    return util.import_app(self.app_uri)
  File "/usr/local/lib/python3.9/site-packages/gunicorn/util.py", line 370, in import_app
    mod = importlib.import_module(module)
  File "/usr/local/lib/python3.9/importlib/__init__.py", line 127, in import_module
    return _bootstrap._gcd_import(name[level:], package, level)
  File "<frozen importlib._bootstrap>", line 1027, in _gcd_import
  File "<frozen importlib._bootstrap>", line 961, in _sanity_check
ValueError: Empty module name
[2025-02-05 17:40:59 +0000] [7] [INFO] Worker exiting (pid: 7)
[2025-02-05 17:40:59 +0000] [8] [INFO] Booting worker with pid: 8
[2025-02-05 17:40:59 +0000] [1] [ERROR] Worker (pid:7) exited with code 3
[2025-02-05 17:40:59 +0000] [8] [ERROR] Exception in worker process
Traceback (most recent call last):
  File "/usr/local/lib/python3.9/site-packages/gunicorn/arbiter.py", line 608, in spawn_worker
    worker.init_process()
  File "/usr/local/lib/python3.9/site-packages/uvicorn/workers.py", line 75, in init_process
    super().init_process()
  File "/usr/local/lib/python3.9/site-packages/gunicorn/workers/base.py", line 135, in init_process
    self.load_wsgi()
  File "/usr/local/lib/python3.9/site-packages/gunicorn/workers/base.py", line 147, in load_wsgi
    self.wsgi = self.app.wsgi()
  File "/usr/local/lib/python3.9/site-packages/gunicorn/app/base.py", line 66, in wsgi
    self.callable = self.load()
  File "/usr/local/lib/python3.9/site-packages/gunicorn/app/wsgiapp.py", line 57, in load
    return self.load_wsgiapp()
  File "/usr/local/lib/python3.9/site-packages/gunicorn/app/wsgiapp.py", line 47, in load_wsgiapp
    return util.import_app(self.app_uri)
  File "/usr/local/lib/python3.9/site-packages/gunicorn/util.py", line 370, in import_app
    mod = importlib.import_module(module)
  File "/usr/local/lib/python3.9/importlib/__init__.py", line 127, in import_module
    return _bootstrap._gcd_import(name[level:], package, level)
  File "<frozen importlib._bootstrap>", line 1027, in _gcd_import
  File "<frozen importlib._bootstrap>", line 961, in _sanity_check
ValueError: Empty module name
[2025-02-05 17:40:59 +0000] [8] [INFO] Worker exiting (pid: 8)
[2025-02-05 17:41:00 +0000] [1] [ERROR] Worker (pid:8) exited with code 3
Traceback (most recent call last):
  File "/usr/local/lib/python3.9/site-packages/gunicorn/arbiter.py", line 201, in run
    self.manage_workers()
  File "/usr/local/lib/python3.9/site-packages/gunicorn/arbiter.py", line 570, in manage_workers
    self.spawn_workers()
  File "/usr/local/lib/python3.9/site-packages/gunicorn/arbiter.py", line 642, in spawn_workers
    time.sleep(0.1 * random.random())
  File "/usr/local/lib/python3.9/site-packages/gunicorn/arbiter.py", line 241, in handle_chld
    self.reap_workers()
  File "/usr/local/lib/python3.9/site-packages/gunicorn/arbiter.py", line 529, in reap_workers
    raise HaltServer(reason, self.WORKER_BOOT_ERROR)
gunicorn.errors.HaltServer: <HaltServer 'Worker failed to boot.' 3>

During handling of the above exception, another exception occurred:

Traceback (most recent call last):
  File "/usr/local/bin/gunicorn", line 8, in <module>
    sys.exit(run())
  File "/usr/local/lib/python3.9/site-packages/gunicorn/app/wsgiapp.py", line 66, in run
    WSGIApplication("%(prog)s [OPTIONS] [APP_MODULE]", prog=prog).run()
  File "/usr/local/lib/python3.9/site-packages/gunicorn/app/base.py", line 235, in run
    super().run()
  File "/usr/local/lib/python3.9/site-packages/gunicorn/app/base.py", line 71, in run
    Arbiter(self).run()
  File "/usr/local/lib/python3.9/site-packages/gunicorn/arbiter.py", line 228, in run
    self.halt(reason=inst.reason, exit_status=inst.exit_status)
  File "/usr/local/lib/python3.9/site-packages/gunicorn/arbiter.py", line 341, in halt
    self.stop()
  File "/usr/local/lib/python3.9/site-packages/gunicorn/arbiter.py", line 395, in stop
    time.sleep(0.1)
  File "/usr/local/lib/python3.9/site-packages/gunicorn/arbiter.py", line 241, in handle_chld
    self.reap_workers()
  File "/usr/local/lib/python3.9/site-packages/gunicorn/arbiter.py", line 529, in reap_workers
    raise HaltServer(reason, self.WORKER_BOOT_ERROR)
gunicorn.errors.HaltServer: <HaltServer 'Worker failed to boot.' 3>
stream closed EOF for default/metrics-server-1-549c7d97bb-mptc9 (metrics-server)
Checking for script in /app/prestart.sh
There is no script /app/prestart.sh
{"loglevel": "info", "workers": 3, "bind": "0.0.0.0:80", "graceful_timeout": 120, "timeout": 120, "keepalive": 5, "errorlog": "-", "accesslog": "-", "workers_per_core": 1.0, "use_max_workers": null, "host": "0.0.0.0", "port": "80"}
[2025-02-05 17:41:51 +0000] [1] [INFO] Starting gunicorn 23.0.0
[2025-02-05 17:41:51 +0000] [1] [INFO] Listening at: http://0.0.0.0:80 (1)
[2025-02-05 17:41:51 +0000] [1] [INFO] Using worker: uvicorn.workers.UvicornWorker
[2025-02-05 17:41:51 +0000] [7] [INFO] Booting worker with pid: 7
[2025-02-05 17:41:51 +0000] [8] [INFO] Booting worker with pid: 8
[2025-02-05 17:41:51 +0000] [7] [ERROR] Exception in worker process
Traceback (most recent call last):
  File "/usr/local/lib/python3.9/site-packages/gunicorn/arbiter.py", line 608, in spawn_worker
    worker.init_process()
  File "/usr/local/lib/python3.9/site-packages/uvicorn/workers.py", line 75, in init_process
    super().init_process()
  File "/usr/local/lib/python3.9/site-packages/gunicorn/workers/base.py", line 135, in init_process
    self.load_wsgi()
  File "/usr/local/lib/python3.9/site-packages/gunicorn/workers/base.py", line 147, in load_wsgi
    self.wsgi = self.app.wsgi()
  File "/usr/local/lib/python3.9/site-packages/gunicorn/app/base.py", line 66, in wsgi
    self.callable = self.load()
  File "/usr/local/lib/python3.9/site-packages/gunicorn/app/wsgiapp.py", line 57, in load
    return self.load_wsgiapp()
  File "/usr/local/lib/python3.9/site-packages/gunicorn/app/wsgiapp.py", line 47, in load_wsgiapp
    return util.import_app(self.app_uri)
  File "/usr/local/lib/python3.9/site-packages/gunicorn/util.py", line 370, in import_app
    mod = importlib.import_module(module)
  File "/usr/local/lib/python3.9/importlib/__init__.py", line 127, in import_module
    return _bootstrap._gcd_import(name[level:], package, level)
  File "<frozen importlib._bootstrap>", line 1027, in _gcd_import
  File "<frozen importlib._bootstrap>", line 961, in _sanity_check
ValueError: Empty module name
[2025-02-05 17:41:51 +0000] [7] [INFO] Worker exiting (pid: 7)
[2025-02-05 17:41:51 +0000] [8] [ERROR] Exception in worker process
Traceback (most recent call last):
  File "/usr/local/lib/python3.9/site-packages/gunicorn/arbiter.py", line 608, in spawn_worker
    worker.init_process()
  File "/usr/local/lib/python3.9/site-packages/uvicorn/workers.py", line 75, in init_process
    super().init_process()
  File "/usr/local/lib/python3.9/site-packages/gunicorn/workers/base.py", line 135, in init_process
    self.load_wsgi()
  File "/usr/local/lib/python3.9/site-packages/gunicorn/workers/base.py", line 147, in load_wsgi
    self.wsgi = self.app.wsgi()
  File "/usr/local/lib/python3.9/site-packages/gunicorn/app/base.py", line 66, in wsgi
    self.callable = self.load()
  File "/usr/local/lib/python3.9/site-packages/gunicorn/app/wsgiapp.py", line 57, in load
    return self.load_wsgiapp()
  File "/usr/local/lib/python3.9/site-packages/gunicorn/app/wsgiapp.py", line 47, in load_wsgiapp
    return util.import_app(self.app_uri)
  File "/usr/local/lib/python3.9/site-packages/gunicorn/util.py", line 370, in import_app
    mod = importlib.import_module(module)
  File "/usr/local/lib/python3.9/importlib/__init__.py", line 127, in import_module
    return _bootstrap._gcd_import(name[level:], package, level)
  File "<frozen importlib._bootstrap>", line 1027, in _gcd_import
  File "<frozen importlib._bootstrap>", line 961, in _sanity_check
ValueError: Empty module name
[2025-02-05 17:41:51 +0000] [8] [INFO] Worker exiting (pid: 8)
[2025-02-05 17:41:51 +0000] [1] [ERROR] Worker (pid:7) exited with code 3
[2025-02-05 17:41:51 +0000] [1] [ERROR] Worker (pid:8) was sent SIGTERM!
[2025-02-05 17:41:51 +0000] [1] [ERROR] Shutting down: Master
[2025-02-05 17:41:51 +0000] [1] [ERROR] Reason: Worker failed to boot.
stream closed EOF for default/metrics-server-1-549c7d97bb-mptc9 (metrics-server)

────────────────────────────────────────────────────────────────────────────────────────────────────────────────────────────────────────────────────────────────────────────────────────────────────────────────────────────────────────────────────────────────────────────────────────────────────────────────────────